<sdf version='1.7'>
  <world name='default'>
    <light name='sun' type='directional'>
      <cast_shadows>1</cast_shadows>
      <pose>0 0 10 0 -0 0</pose>
      <diffuse>0.8 0.8 0.8 1</diffuse>
      <specular>0.2 0.2 0.2 1</specular>
      <attenuation>
        <range>1000</range>
        <constant>0.9</constant>
        <linear>0.01</linear>
        <quadratic>0.001</quadratic>
      </attenuation>
      <direction>-0.5 0.1 -0.9</direction>
      <spot>
        <inner_angle>0</inner_angle>
        <outer_angle>0</outer_angle>
        <falloff>0</falloff>
      </spot>
    </light>
    <model name='ground_plane'>
      <static>1</static>
      <link name='link'>
        <collision name='collision'>
          <geometry>
            <plane>
              <normal>0 0 1</normal>
              <size>100 100</size>
            </plane>
          </geometry>
          <surface>
            <friction>
              <ode>
                <mu>100</mu>
                <mu2>50</mu2>
              </ode>
              <torsional>
                <ode/>
              </torsional>
            </friction>
            <contact>
              <ode/>
            </contact>
            <bounce/>
          </surface>
          <max_contacts>10</max_contacts>
        </collision>
        <visual name='visual'>
          <cast_shadows>0</cast_shadows>
          <geometry>
            <plane>
              <normal>0 0 1</normal>
              <size>100 100</size>
            </plane>
          </geometry>
          <material>
            <script>
              <uri>file://media/materials/scripts/gazebo.material</uri>
              <name>Gazebo/Grey</name>
            </script>
          </material>
        </visual>
        <self_collide>0</self_collide>
        <enable_wind>0</enable_wind>
        <kinematic>0</kinematic>
      </link>
    </model>
    <gravity>0 0 -9.8</gravity>
    <magnetic_field>6e-06 2.3e-05 -4.2e-05</magnetic_field>
    <atmosphere type='adiabatic'/>
    <physics type='ode'>
      <max_step_size>0.001</max_step_size>
      <real_time_factor>1</real_time_factor>
      <real_time_update_rate>1000</real_time_update_rate>
    </physics>
    <scene>
      <ambient>0.4 0.4 0.4 1</ambient>
      <background>0.7 0.7 0.7 1</background>
      <shadows>1</shadows>
    </scene>
    <wind/>
    <spherical_coordinates>
      <surface_model>EARTH_WGS84</surface_model>
      <latitude_deg>0</latitude_deg>
      <longitude_deg>0</longitude_deg>
      <elevation>0</elevation>
      <heading_deg>0</heading_deg>
    </spherical_coordinates>
    <state world_name='default'>
      <sim_time>375 648000000</sim_time>
      <real_time>8 255308431</real_time>
      <wall_time>1711779780 402182463</wall_time>
      <iterations>6258</iterations>
      <model name='2024uc'>
        <pose>0.414928 -2.00543 0.102371 -0.00079 -0 -5.6e-05</pose>
        <scale>1 1 1</scale>
        <link name='link_0'>
          <pose>6.01526 3.99418 -0.002369 -1.57079 -0 -5.6e-05</pose>
          <velocity>0 0 0 0 -0 0</velocity>
          <acceleration>0 0 0 0 -0 0</acceleration>
          <wrench>0 0 0 0 -0 0</wrench>
        </link>
      </model>
      <model name='ground_plane'>
        <pose>0 0 0 0 -0 0</pose>
        <scale>1 1 1</scale>
        <link name='link'>
          <pose>0 0 0 0 -0 0</pose>
          <velocity>0 0 0 0 -0 0</velocity>
          <acceleration>0 0 0 0 -0 0</acceleration>
          <wrench>0 0 0 0 -0 0</wrench>
        </link>
      </model>
      <model name='mowen_4wd_mecanum'>
        <pose>2.98046 2.96076 0 -0 -0 -0.026418</pose>
        <scale>1 1 1</scale>
        <link name='base_footprint'>
          <pose>2.98046 2.96076 0 -0 -0 -0.026418</pose>
          <velocity>-9.8e-05 -0.00083 8e-06 2.9e-05 -1e-06 -8.1e-05</velocity>
          <acceleration>0 -6.5e-05 0.015581 0.057625 -0.002516 0.00023</acceleration>
          <wrench>1e-06 -0.000205 0.049299 0 -0 0</wrench>
        </link>
        <link name='lower_left_wheel'>
          <pose>2.83447 3.11467 0.05 -4e-06 5e-06 -0.026418</pose>
          <velocity>-8.5e-05 -0.000819 1.5e-05 -0.000735 2e-05 -8.1e-05</velocity>
          <acceleration>-3e-05 0.000105 0.030613 -1.46925 0.051374 0.000229</acceleration>
          <wrench>-1.1e-05 4e-05 0.011768 0 -0 0</wrench>
        </link>
        <link name='lower_right_wheel'>
          <pose>2.82655 2.81477 0.05 3.14159 3e-06 -0.026418</pose>
          <velocity>-0.00011 -0.000819 0 9.4e-05 -2e-06 -8.1e-05</velocity>
          <acceleration>3.9e-05 8.1e-05 0.000952 0.187318 -0.00655 0.000312</acceleration>
          <wrench>1.5e-05 3.1e-05 0.000366 0 -0 0</wrench>
        </link>
        <link name='upper_left_wheel'>
          <pose>3.13437 3.10674 0.05 -4e-06 2e-06 -0.026418</pose>
          <velocity>-8.6e-05 -0.000844 1.5e-05 -0.000735 1.9e-05 -8.1e-05</velocity>
          <acceleration>-5.2e-05 0.000199 0.030599 -1.46963 0.051387 0.000229</acceleration>
          <wrench>-2e-05 7.6e-05 0.011762 0 -0 0</wrench>
        </link>
        <link name='upper_right_wheel'>
          <pose>3.12644 2.80685 0.05 3.14159 -2e-06 -0.026418</pose>
          <velocity>-0.00011 -0.000843 0 9.3e-05 -3e-06 -8.1e-05</velocity>
          <acceleration>4.1e-05 0.00015 0.000956 0.186523 -0.006522 0.000312</acceleration>
          <wrench>1.6e-05 5.8e-05 0.000368 0 -0 0</wrench>
        </link>
      </model>
      <light name='sun'>
        <pose>0 0 10 0 -0 0</pose>
      </light>
    </state>
    <gui fullscreen='0'>
      <camera name='user_camera'>
        <pose>5.74112 -5.46247 12.0562 0 0.961801 1.56725</pose>
        <view_controller>orbit</view_controller>
        <projection_type>perspective</projection_type>
      </camera>
    </gui>
    <model name='mowen_4wd_mecanum'>
      <link name='base_footprint'>
        <inertial>
          <pose>-0.00511 0 0.053125 0 -0 0</pose>
          <mass>3.164</mass>
          <inertia>
            <ixx>0.0322414</ixx>
            <ixy>-4.43257e-21</ixy>
            <ixz>-0.000727712</ixz>
            <iyy>0.0750542</iyy>
            <iyz>2.41578e-20</iyz>
            <izz>0.0949901</izz>
          </inertia>
        </inertial>
        <collision name='base_footprint_fixed_joint_lump__base_link_collision'>
          <pose>0 0 0.05 0 -0 0</pose>
          <geometry>
            <mesh>
              <scale>0.001 0.001 0.001</scale>
              <uri>/home/dji/RMUC24/src/RMUC24_simulation/mowen_4wd_mecanum_description/meshes/mowen_base_link_collision.STL</uri>
            </mesh>
          </geometry>
          <surface>
            <contact>
              <ode/>
            </contact>
            <friction>
              <ode/>
              <torsional>
                <ode/>
              </torsional>
            </friction>
            <bounce/>
          </surface>
          <max_contacts>10</max_contacts>
        </collision>
        <collision name='base_footprint_fixed_joint_lump__laser_link_collision_1'>
          <pose>0.152 0 0.092 0 -0 0</pose>
          <geometry>
            <cylinder>
              <length>0.035</length>
              <radius>0.02</radius>
            </cylinder>
          </geometry>
          <surface>
            <contact>
              <ode/>
            </contact>
            <friction>
              <ode/>
              <torsional>
                <ode/>
              </torsional>
            </friction>
            <bounce/>
          </surface>
          <max_contacts>10</max_contacts>
        </collision>
        <collision name='base_footprint_fixed_joint_lump__lower_left_wheel_shaft_collision_2'>
          <pose>-0.15 0.108 0.05 0 -0 0</pose>
          <geometry>
            <mesh>
              <scale>0.001 0.001 0.001</scale>
              <uri>/home/dji/RMUC24/src/RMUC24_simulation/mowen_4wd_mecanum_description/meshes/wheel_shaft.STL</uri>
            </mesh>
          </geometry>
          <surface>
            <contact>
              <ode/>
            </contact>
            <friction>
              <ode/>
              <torsional>
                <ode/>
              </torsional>
            </friction>
            <bounce/>
          </surface>
          <max_contacts>10</max_contacts>
        </collision>
        <collision name='base_footprint_fixed_joint_lump__lower_right_wheel_shaft_collision_3'>
          <pose>-0.15 -0.108 0.05 3.14159 -0 0</pose>
          <geometry>
            <mesh>
              <scale>0.001 0.001 0.001</scale>
              <uri>/home/dji/RMUC24/src/RMUC24_simulation/mowen_4wd_mecanum_description/meshes/wheel_shaft.STL</uri>
            </mesh>
          </geometry>
          <surface>
            <contact>
              <ode/>
            </contact>
            <friction>
              <ode/>
              <torsional>
                <ode/>
              </torsional>
            </friction>
            <bounce/>
          </surface>
          <max_contacts>10</max_contacts>
        </collision>
        <collision name='base_footprint_fixed_joint_lump__upper_left_wheel_shaft_collision_4'>
          <pose>0.15 0.108 0.05 0 -0 0</pose>
          <geometry>
            <mesh>
              <scale>0.001 0.001 0.001</scale>
              <uri>/home/dji/RMUC24/src/RMUC24_simulation/mowen_4wd_mecanum_description/meshes/wheel_shaft.STL</uri>
            </mesh>
          </geometry>
          <surface>
            <contact>
              <ode/>
            </contact>
            <friction>
              <ode/>
              <torsional>
                <ode/>
              </torsional>
            </friction>
            <bounce/>
          </surface>
          <max_contacts>10</max_contacts>
        </collision>
        <collision name='base_footprint_fixed_joint_lump__upper_right_wheel_shaft_collision_5'>
          <pose>0.15 -0.108 0.05 3.14159 -0 0</pose>
          <geometry>
            <mesh>
              <scale>0.001 0.001 0.001</scale>
              <uri>/home/dji/RMUC24/src/RMUC24_simulation/mowen_4wd_mecanum_description/meshes/wheel_shaft.STL</uri>
            </mesh>
          </geometry>
          <surface>
            <contact>
              <ode/>
            </contact>
            <friction>
              <ode/>
              <torsional>
                <ode/>
              </torsional>
            </friction>
            <bounce/>
          </surface>
          <max_contacts>10</max_contacts>
        </collision>
        <visual name='base_footprint_fixed_joint_lump__base_link_visual'>
          <pose>0 0 0.05 0 -0 0</pose>
          <geometry>
            <mesh>
              <scale>0.001 0.001 0.001</scale>
              <uri>/home/dji/RMUC24/src/RMUC24_simulation/mowen_4wd_mecanum_description/meshes/mowen_base_link.STL</uri>
            </mesh>
          </geometry>
          <material>
            <script>
              <name>Gazebo/Grey</name>
              <uri>file://media/materials/scripts/gazebo.material</uri>
            </script>
          </material>
        </visual>
        <visual name='base_footprint_fixed_joint_lump__laser_link_visual_1'>
          <pose>0.152 0 0.092 0 -0 0</pose>
          <geometry>
            <cylinder>
              <length>0.035</length>
              <radius>0.02</radius>
            </cylinder>
          </geometry>
          <material>
            <script>
              <name>Gazebo/BlueTransparent</name>
              <uri>file://media/materials/scripts/gazebo.material</uri>
            </script>
          </material>
        </visual>
        <visual name='base_footprint_fixed_joint_lump__lower_left_wheel_shaft_visual_2'>
          <pose>-0.15 0.108 0.05 0 -0 0</pose>
          <geometry>
            <mesh>
              <scale>0.001 0.001 0.001</scale>
              <uri>/home/dji/RMUC24/src/RMUC24_simulation/mowen_4wd_mecanum_description/meshes/wheel_shaft.STL</uri>
            </mesh>
          </geometry>
          <material>
            <script>
              <name>Gazebo/Black</name>
              <uri>file://media/materials/scripts/gazebo.material</uri>
            </script>
          </material>
        </visual>
        <visual name='base_footprint_fixed_joint_lump__lower_right_wheel_shaft_visual_3'>
          <pose>-0.15 -0.108 0.05 3.14159 -0 0</pose>
          <geometry>
            <mesh>
              <scale>0.001 0.001 0.001</scale>
              <uri>/home/dji/RMUC24/src/RMUC24_simulation/mowen_4wd_mecanum_description/meshes/wheel_shaft.STL</uri>
            </mesh>
          </geometry>
          <material>
            <script>
              <name>Gazebo/Black</name>
              <uri>file://media/materials/scripts/gazebo.material</uri>
            </script>
          </material>
        </visual>
        <visual name='base_footprint_fixed_joint_lump__upper_left_wheel_shaft_visual_4'>
          <pose>0.15 0.108 0.05 0 -0 0</pose>
          <geometry>
            <mesh>
              <scale>0.001 0.001 0.001</scale>
              <uri>/home/dji/RMUC24/src/RMUC24_simulation/mowen_4wd_mecanum_description/meshes/wheel_shaft.STL</uri>
            </mesh>
          </geometry>
          <material>
            <script>
              <name>Gazebo/Black</name>
              <uri>file://media/materials/scripts/gazebo.material</uri>
            </script>
          </material>
        </visual>
        <visual name='base_footprint_fixed_joint_lump__upper_right_wheel_shaft_visual_5'>
          <pose>0.15 -0.108 0.05 3.14159 -0 0</pose>
          <geometry>
            <mesh>
              <scale>0.001 0.001 0.001</scale>
              <uri>/home/dji/RMUC24/src/RMUC24_simulation/mowen_4wd_mecanum_description/meshes/wheel_shaft.STL</uri>
            </mesh>
          </geometry>
          <material>
            <script>
              <name>Gazebo/Black</name>
              <uri>file://media/materials/scripts/gazebo.material</uri>
            </script>
          </material>
        </visual>
        <gravity>1</gravity>
        <sensor name='rplidar' type='ray'>
          <visualize>0</visualize>
          <update_rate>5.5</update_rate>
          <ray>
            <scan>
              <horizontal>
                <samples>360</samples>
                <resolution>1</resolution>
                <min_angle>-1.36</min_angle>
                <max_angle>1.36</max_angle>
              </horizontal>
              <vertical>
                <samples>1</samples>
                <min_angle>0</min_angle>
                <max_angle>0</max_angle>
              </vertical>
            </scan>
            <range>
              <min>0.1</min>
              <max>6</max>
              <resolution>0.01</resolution>
            </range>
            <noise>
              <type>gaussian</type>
              <mean>0</mean>
              <stddev>0.01</stddev>
            </noise>
          </ray>
          <plugin name='gazebo_rplidar' filename='libgazebo_ros_laser.so'>
            <topicName>/scan</topicName>
            <frameName>laser_link</frameName>
            <robotNamespace>/</robotNamespace>
          </plugin>
          <pose>0.152 0 0.092 0 -0 0</pose>
        </sensor>
        <self_collide>0</self_collide>
        <enable_wind>0</enable_wind>
        <kinematic>0</kinematic>
      </link>
      <joint name='lower_left_wheel_joint' type='revolute'>
        <pose relative_to='base_footprint'>-0.15 0.15 0.05 0 -0 0</pose>
        <parent>base_footprint</parent>
        <child>lower_left_wheel</child>
        <axis>
          <xyz>0 1 0</xyz>
          <limit>
            <lower>-1e+16</lower>
            <upper>1e+16</upper>
          </limit>
          <dynamics>
            <spring_reference>0</spring_reference>
            <spring_stiffness>0</spring_stiffness>
          </dynamics>
        </axis>
      </joint>
      <link name='lower_left_wheel'>
        <pose relative_to='lower_left_wheel_joint'>0 0 0 0 -0 0</pose>
        <inertial>
          <pose>0 0 0 0 -0 0</pose>
          <mass>0.3844</mass>
          <inertia>
            <ixx>0.000324824</ixx>
            <ixy>0</ixy>
            <ixz>0</ixz>
            <iyy>0.00048</iyy>
            <iyz>0</iyz>
            <izz>0.000324824</izz>
          </inertia>
        </inertial>
        <collision name='lower_left_wheel_collision'>
          <pose>0 0 0 1.5708 -0 0</pose>
          <geometry>
            <cylinder>
              <length>0.0505</length>
              <radius>0.05</radius>
            </cylinder>
          </geometry>
          <surface>
            <contact>
              <ode/>
            </contact>
            <friction>
              <ode>
                <mu>0</mu>
                <mu2>0</mu2>
              </ode>
              <torsional>
                <ode/>
              </torsional>
            </friction>
            <bounce/>
          </surface>
          <max_contacts>10</max_contacts>
        </collision>
        <visual name='lower_left_wheel_visual'>
          <pose>0 0 0 0 -0 0</pose>
          <geometry>
            <mesh>
              <scale>0.001 0.001 0.001</scale>
              <uri>/home/dji/RMUC24/src/RMUC24_simulation/mowen_4wd_mecanum_description/meshes/mecanum_wheel_right.STL</uri>
            </mesh>
          </geometry>
          <material>
            <script>
              <name>Gazebo/DarkGrey</name>
              <uri>file://media/materials/scripts/gazebo.material</uri>
            </script>
          </material>
        </visual>
        <self_collide>0</self_collide>
        <enable_wind>0</enable_wind>
        <kinematic>0</kinematic>
      </link>
      <joint name='lower_right_wheel_joint' type='revolute'>
        <pose relative_to='base_footprint'>-0.15 -0.15 0.05 3.14159 -0 0</pose>
        <parent>base_footprint</parent>
        <child>lower_right_wheel</child>
        <axis>
          <xyz>0 1 0</xyz>
          <limit>
            <lower>-1e+16</lower>
            <upper>1e+16</upper>
          </limit>
          <dynamics>
            <spring_reference>0</spring_reference>
            <spring_stiffness>0</spring_stiffness>
          </dynamics>
        </axis>
      </joint>
      <link name='lower_right_wheel'>
        <pose relative_to='lower_right_wheel_joint'>0 0 0 0 -0 0</pose>
        <inertial>
          <pose>0 0 0 0 -0 0</pose>
          <mass>0.3844</mass>
          <inertia>
            <ixx>0.000324824</ixx>
            <ixy>0</ixy>
            <ixz>0</ixz>
            <iyy>0.00048</iyy>
            <iyz>0</iyz>
            <izz>0.000324824</izz>
          </inertia>
        </inertial>
        <collision name='lower_right_wheel_collision'>
          <pose>0 0 0 1.5708 -0 0</pose>
          <geometry>
            <cylinder>
              <length>0.0505</length>
              <radius>0.05</radius>
            </cylinder>
          </geometry>
          <surface>
            <contact>
              <ode/>
            </contact>
            <friction>
              <ode>
                <mu>0</mu>
                <mu2>0</mu2>
              </ode>
              <torsional>
                <ode/>
              </torsional>
            </friction>
            <bounce/>
          </surface>
          <max_contacts>10</max_contacts>
        </collision>
        <visual name='lower_right_wheel_visual'>
          <pose>0 0 0 0 -0 0</pose>
          <geometry>
            <mesh>
              <scale>0.001 0.001 0.001</scale>
              <uri>/home/dji/RMUC24/src/RMUC24_simulation/mowen_4wd_mecanum_description/meshes/mecanum_wheel_left.STL</uri>
            </mesh>
          </geometry>
          <material>
            <script>
              <name>Gazebo/DarkGrey</name>
              <uri>file://media/materials/scripts/gazebo.material</uri>
            </script>
          </material>
        </visual>
        <self_collide>0</self_collide>
        <enable_wind>0</enable_wind>
        <kinematic>0</kinematic>
      </link>
      <joint name='upper_left_wheel_joint' type='revolute'>
        <pose relative_to='base_footprint'>0.15 0.15 0.05 0 -0 0</pose>
        <parent>base_footprint</parent>
        <child>upper_left_wheel</child>
        <axis>
          <xyz>0 1 0</xyz>
          <limit>
            <lower>-1e+16</lower>
            <upper>1e+16</upper>
          </limit>
          <dynamics>
            <spring_reference>0</spring_reference>
            <spring_stiffness>0</spring_stiffness>
          </dynamics>
        </axis>
      </joint>
      <link name='upper_left_wheel'>
        <pose relative_to='upper_left_wheel_joint'>0 0 0 0 -0 0</pose>
        <inertial>
          <pose>0 0 0 0 -0 0</pose>
          <mass>0.3844</mass>
          <inertia>
            <ixx>0.000324824</ixx>
            <ixy>0</ixy>
            <ixz>0</ixz>
            <iyy>0.00048</iyy>
            <iyz>0</iyz>
            <izz>0.000324824</izz>
          </inertia>
        </inertial>
        <collision name='upper_left_wheel_collision'>
          <pose>0 0 0 1.5708 -0 0</pose>
          <geometry>
            <cylinder>
              <length>0.0505</length>
              <radius>0.05</radius>
            </cylinder>
          </geometry>
          <surface>
            <contact>
              <ode/>
            </contact>
            <friction>
              <ode>
                <mu>0</mu>
                <mu2>0</mu2>
              </ode>
              <torsional>
                <ode/>
              </torsional>
            </friction>
            <bounce/>
          </surface>
          <max_contacts>10</max_contacts>
        </collision>
        <visual name='upper_left_wheel_visual'>
          <pose>0 0 0 0 -0 0</pose>
          <geometry>
            <mesh>
              <scale>0.001 0.001 0.001</scale>
              <uri>/home/dji/RMUC24/src/RMUC24_simulation/mowen_4wd_mecanum_description/meshes/mecanum_wheel_left.STL</uri>
            </mesh>
          </geometry>
          <material>
            <script>
              <name>Gazebo/DarkGrey</name>
              <uri>file://media/materials/scripts/gazebo.material</uri>
            </script>
          </material>
        </visual>
        <self_collide>0</self_collide>
        <enable_wind>0</enable_wind>
        <kinematic>0</kinematic>
      </link>
      <joint name='upper_right_wheel_joint' type='revolute'>
        <pose relative_to='base_footprint'>0.15 -0.15 0.05 3.14159 -0 0</pose>
        <parent>base_footprint</parent>
        <child>upper_right_wheel</child>
        <axis>
          <xyz>0 1 0</xyz>
          <limit>
            <lower>-1e+16</lower>
            <upper>1e+16</upper>
          </limit>
          <dynamics>
            <spring_reference>0</spring_reference>
            <spring_stiffness>0</spring_stiffness>
          </dynamics>
        </axis>
      </joint>
      <link name='upper_right_wheel'>
        <pose relative_to='upper_right_wheel_joint'>0 0 0 0 -0 0</pose>
        <inertial>
          <pose>0 0 0 0 -0 0</pose>
          <mass>0.3844</mass>
          <inertia>
            <ixx>0.000324824</ixx>
            <ixy>0</ixy>
            <ixz>0</ixz>
            <iyy>0.00048</iyy>
            <iyz>0</iyz>
            <izz>0.000324824</izz>
          </inertia>
        </inertial>
        <collision name='upper_right_wheel_collision'>
          <pose>0 0 0 1.5708 -0 0</pose>
          <geometry>
            <cylinder>
              <length>0.0505</length>
              <radius>0.05</radius>
            </cylinder>
          </geometry>
          <surface>
            <contact>
              <ode/>
            </contact>
            <friction>
              <ode>
                <mu>0</mu>
                <mu2>0</mu2>
              </ode>
              <torsional>
                <ode/>
              </torsional>
            </friction>
            <bounce/>
          </surface>
          <max_contacts>10</max_contacts>
        </collision>
        <visual name='upper_right_wheel_visual'>
          <pose>0 0 0 0 -0 0</pose>
          <geometry>
            <mesh>
              <scale>0.001 0.001 0.001</scale>
              <uri>/home/dji/RMUC24/src/RMUC24_simulation/mowen_4wd_mecanum_description/meshes/mecanum_wheel_right.STL</uri>
            </mesh>
          </geometry>
          <material>
            <script>
              <name>Gazebo/DarkGrey</name>
              <uri>file://media/materials/scripts/gazebo.material</uri>
            </script>
          </material>
        </visual>
        <self_collide>0</self_collide>
        <enable_wind>0</enable_wind>
        <kinematic>0</kinematic>
      </link>
      <static>0</static>
      <plugin name='mowen_ros_force_based_move' filename='libmowen_ros_force_based_move.so'>
        <commandTopic>cmd_vel</commandTopic>
        <odometryTopic>odom</odometryTopic>
        <odometryFrame>odom</odometryFrame>
        <odometryRate>25.0</odometryRate>
        <robotBaseFrame>base_footprint</robotBaseFrame>
        <cmdVelTimeOut>0.25</cmdVelTimeOut>
        <publishOdometryTf>1</publishOdometryTf>
        <yaw_velocity_p_gain>1.0</yaw_velocity_p_gain>
        <x_velocity_p_gain>15.0</x_velocity_p_gain>
        <y_velocity_p_gain>15.0</y_velocity_p_gain>
        <max_x_velocity>0.6</max_x_velocity>
        <max_y_velocity>0.6</max_y_velocity>
        <max_yaw_velocity>0.5</max_yaw_velocity>
        <robotNamespace>/</robotNamespace>
      </plugin>
      <pose>3 3.2 0.2 0 -0 0</pose>
    </model>
    <model name='2024uc'>
      <link name='link_0'>
        <inertial>
          <mass>1</mass>
          <inertia>
            <ixx>0.166667</ixx>
            <ixy>0</ixy>
            <ixz>0</ixz>
            <iyy>0.166667</iyy>
            <iyz>0</iyz>
            <izz>0.166667</izz>
          </inertia>
          <pose>0 0 0 0 -0 0</pose>
        </inertial>
        <pose>5.6 6 -0.21 -1.57 0 0</pose>
        <gravity>1</gravity>
        <self_collide>0</self_collide>
        <kinematic>0</kinematic>
        <enable_wind>0</enable_wind>
        <visual name='visual'>
          <pose>0 0 0 0 -0 0</pose>
          <geometry>
            <mesh>
              <uri>/home/dji/RMUC24/src/RMUC24_simulation/fp_sim/world/2024RMUC/2024uc.stl</uri>
              <scale>0.001 0.001 0.001</scale>
            </mesh>
          </geometry>
          <material>
            <lighting>1</lighting>
            <script>
              <uri>file://media/materials/scripts/gazebo.material</uri>
              <name>Gazebo/Grey</name>
            </script>
            <shader type='pixel'>
              <normal_map>__default__</normal_map>
            </shader>
            <ambient>0.3 0.3 0.3 1</ambient>
            <diffuse>1 1 1 1</diffuse>
            <specular>0.01 0.01 0.01 1</specular>
            <emissive>0.333 0.341 0.325 1</emissive>
          </material>
          <transparency>0</transparency>
          <cast_shadows>1</cast_shadows>
        </visual>
        <collision name='collision'>
          <laser_retro>0</laser_retro>
          <max_contacts>10</max_contacts>
          <pose>0 0 0 0 -0 0</pose>
          <geometry>
            <mesh>
              <uri>/home/dji/RMUC24/src/RMUC24_simulation/fp_sim/world/2024RMUC/2024uc.stl</uri>
              <scale>0.001 0.001 0.001</scale>
            </mesh>
          </geometry>
          <surface>
            <friction>
              <ode>
                <mu>1</mu>
                <mu2>1</mu2>
                <fdir1>0 0 0</fdir1>
                <slip1>0</slip1>
                <slip2>0</slip2>
              </ode>
              <torsional>
                <coefficient>1</coefficient>
                <patch_radius>0</patch_radius>
                <surface_radius>0</surface_radius>
                <use_patch_radius>1</use_patch_radius>
                <ode>
                  <slip>0</slip>
                </ode>
              </torsional>
            </friction>
            <bounce>
              <restitution_coefficient>0</restitution_coefficient>
              <threshold>1e+06</threshold>
            </bounce>
            <contact>
              <collide_without_contact>0</collide_without_contact>
              <collide_without_contact_bitmask>1</collide_without_contact_bitmask>
              <collide_bitmask>1</collide_bitmask>
              <ode>
                <soft_cfm>0</soft_cfm>
                <soft_erp>0.2</soft_erp>
                <kp>1e+13</kp>
                <kd>1</kd>
                <max_vel>0.01</max_vel>
                <min_depth>0</min_depth>
              </ode>
              <bullet>
                <split_impulse>1</split_impulse>
                <split_impulse_penetration_threshold>-0.01</split_impulse_penetration_threshold>
                <soft_cfm>0</soft_cfm>
                <soft_erp>0.2</soft_erp>
                <kp>1e+13</kp>
                <kd>1</kd>
              </bullet>
            </contact>
          </surface>
        </collision>
      </link>
      <static>1</static>
      <allow_auto_disable>1</allow_auto_disable>
      <pose>0.414857 -2.0052 0.204783 -0.000798 -0 -6.2e-05</pose>
    </model>
  </world>
</sdf>
